tests/64_threads/sample_83.in
64
o
50 S 102 3 198 404
53 B 105 4 173 151
55 B 107 5 175 443
32 B 108 0 155 736
4 B 111 7 131 908
38 S 112 5 169 259
53 B 113 7 167 58
33 S 115 1 100 721
33 S 116 5 187 850
22 S 117 4 146 100
44 B 120 2 101 247
6 S 121 0 198 125
14 B 122 8 111 755
26 B 124 6 178 312
27 S 125 5 146 464
32 C 108
9 S 129 5 136 732
47 S 130 1 140 738
28 S 131 7 138 688
38 B 132 8 139 656
30 S 133 5 117 167
55 B 134 3 172 10
47 B 135 0 175 82
15 S 136 5 177 114
25 S 137 0 142 934
56 S 138 9 112 676
38 B 140 1 167 368
55 S 141 6 147 656
42 B 142 4 152 137
32 C 108
59 S 145 8 189 108
17 S 146 0 196 260
4 S 147 2 156 448
15 S 149 9 111 163
46 S 150 3 133 779
36 S 152 4 168 80
50 S 154 2 149 240
11 S 157 2 131 781
29 S 158 2 179 328
44 S 159 7 166 768
26 S 161 5 147 388
9 C 129
45 B 164 3 136 28
18 S 165 0 148 572
2 S 166 4 118 530
19 S 167 3 195 67
8 B 168 1 158 519
35 B 171 6 122 965
60 B 172 1 124 832
32 S 174 7 190 674
20 B 175 4 185 160
34 S 176 2 166 514
46 C 150
31 S 178 1 171 47
55 B 182 9 101 976
36 S 183 1 120 183
44 B 186 8 150 578
56 C 138
62 B 188 9 159 46
50 S 189 0 117 224
12 B 191 1 188 285
43 B 192 1 114 243
35 S 193 3 154 962
32 B 194 4 193 461
42 C 142
13 B 196 2 152 893
53 C 105
52 B 199 7 116 955
60 S 201 9 193 337
15 C 136
46 B 203 6 182 658
52 S 205 8 166 997
17 B 206 0 136 86
55 C 141
60 B 208 2 159 523
15 C 136
45 C 164
5 B 211 2 162 733
46 B 212 8 125 559
4 S 213 5 129 921
55 B 214 5 178 36
30 S 215 7 197 117
48 S 216 9 170 605
35 C 193
5 C 211
2 C 166
9 S 220 1 140 952
34 B 221 5 193 866
21 B 222 9 136 348
25 B 223 2 142 994
42 B 224 6 158 338
38 C 112
28 B 226 7 138 269
54 S 228 5 125 180
60 B 229 6 185 105
6 C 121
31 S 232 2 121 732
61 B 233 7 125 534
27 S 235 6 174 908
59 S 236 4 138 778
25 C 137
5 B 238 5 157 819
27 B 239 4 111 352
30 C 133
29 S 241 9 129 514
38 B 242 5 189 470
17 C 146
18 B 245 8 168 59
40 S 246 6 134 524
63 S 247 2 162 681
53 S 248 0 107 97
33 C 116
58 S 251 8 105 133
53 B 253 8 159 945
9 B 254 5 118 931
18 S 255 8 145 990
12 S 256 0 122 437
43 S 257 5 189 170
26 C 124
36 C 183
48 C 216
29 S 261 8 102 126
18 B 262 9 152 126
13 B 263 0 164 863
42 S 266 4 111 220
59 S 267 1 161 383
53 C 253
36 S 269 9 179 239
2 B 270 9 198 531
29 C 158
1 B 272 7 173 189
62 S 273 9 121 499
1 S 274 7 159 495
11 S 275 5 118 359
60 S 276 5 106 793
21 S 277 6 109 918
32 B 278 5 157 36
36 S 280 8 120 703
6 B 282 9 115 832
22 B 283 4 192 431
14 S 284 7 173 864
48 B 285 4 138 872
54 C 228
44 S 288 1 103 884
33 C 116
46 S 290 7 125 167
42 B 291 5 113 820
54 C 228
54 B 293 8 100 808
60 C 201
34 B 295 2 144 691
38 C 132
21 C 222
26 C 124
62 C 273
49 B 301 9 151 275
34 B 302 1 134 390
38 S 303 7 138 487
63 C 247
16 S 305 3 103 427
21 S 306 2 155 177
47 S 308 6 196 407
33 S 309 2 130 859
21 B 310 4 148 974
11 S 311 2 148 560
31 B 312 1 185 655
63 S 313 0 185 678
12 B 314 7 171 214
43 S 315 7 177 401
14 C 284
31 B 317 1 164 961
13 S 318 1 121 984
51 S 319 3 160 83
7 S 320 2 103 864
17 S 321 6 148 14
5 C 211
20 B 323 0 107 603
59 B 324 5 194 958
19 C 167
63 C 247
44 C 288
37 B 328 4 114 952
7 S 329 5 193 817
45 S 331 9 101 277
62 B 332 8 169 260
56 B 333 0 178 874
17 S 334 6 140 756
25 C 223
62 B 336 0 161 519
29 S 337 3 200 119
15 S 338 4 126 639
21 S 339 7 115 730
56 C 333
18 S 341 9 184 735
53 B 342 8 139 394
29 C 337
16 S 344 9 177 722
27 S 345 0 109 972
63 C 247
7 S 347 4 104 412
7 B 348 8 170 908
15 C 338
4 B 350 3 186 627
57 S 351 6 117 556
36 C 152
22 C 283
21 C 306
40 B 355 1 138 720
50 C 154
9 C 254
35 B 358 2 109 769
43 B 359 8 188 236
44 B 360 4 169 193
52 B 361 6 159 226
24 S 362 3 125 956
34 C 295
35 C 171
33 C 309
45 S 366 3 156 477
10 S 367 0 133 451
46 C 290
2 S 369 9 148 592
50 C 154
16 C 305
29 B 372 7 191 236
36 B 373 4 134 468
54 B 374 3 159 390
5 C 238
47 B 376 8 156 452
3 S 377 9 163 424
51 S 378 8 199 867
30 B 379 7 132 420
10 B 380 7 194 298
23 B 381 7 138 669
23 C 381
55 C 182
4 C 111
28 S 385 8 114 271
56 C 138
14 S 387 8 157 555
45 B 388 5 156 645
25 C 137
21 S 390 0 141 404
21 B 391 2 155 208
27 S 392 4 158 732
5 C 238
47 C 135
51 B 395 3 103 309
49 C 301
12 S 397 0 184 25
11 S 398 5 142 816
43 S 399 4 140 933
62 C 332
45 B 401 2 127 406
23 C 381
13 B 403 8 107 346
9 B 404 2 110 183
36 C 152
46 B 406 5 175 978
55 B 407 1 169 981
49 C 301
35 B 409 4 125 603
25 S 410 7 111 48
19 B 411 8 175 990
13 C 263
26 S 413 0 192 46
15 B 414 1 126 223
4 C 350
6 S 416 5 119 475
35 B 417 7 193 400
18 S 418 3 175 399
37 S 419 7 128 322
23 S 420 6 146 124
18 C 165
61 B 422 0 146 208
49 C 301
2 C 166
27 S 425 7 142 100
21 S 426 5 151 779
40 B 427 9 135 611
62 C 273
42 B 429 8 144 934
47 B 430 4 147 429
28 C 226
9 S 432 2 132 745
23 C 381
17 B 434 9 107 829
60 C 208
19 B 436 7 186 219
36 B 437 3 188 515
16 C 344
16 S 439 0 127 508
56 S 440 0 149 770
15 C 338
18 C 245
41 B 443 4 100 647
14 B 444 2 145 11
23 S 445 8 156 709
3 S 446 4 126 144
22 S 447 9 133 798
53 S 448 6 162 884
5 S 449 9 144 16
25 S 450 9 132 949
57 S 451 3 187 791
23 S 452 3 143 414
1 S 453 6 147 403
62 S 454 0 187 312
40 B 455 2 162 673
1 C 274
25 C 223
27 B 458 4 142 427
38 C 242
14 C 122
44 B 461 8 111 427
18 C 418
28 C 385
3 B 464 8 162 229
44 C 186
30 B 466 0 170 264
50 C 189
59 B 468 2 128 579
45 S 469 8 153 515
10 C 367
51 B 471 0 188 524
41 S 472 7 130 184
35 S 473 9 127 483
9 B 474 4 191 969
53 S 475 6 196 266
1 S 476 8 117 523
16 C 305
3 C 446
3 S 479 8 168 414
33 B 480 1 124 652
18 C 255
34 C 302
2 S 483 5 132 165
20 C 323
62 B 485 6 197 192
15 B 486 5 197 375
4 B 487 6 119 296
6 S 488 8 122 973
27 B 489 1 187 205
28 C 226
21 S 491 7 143 405
46 B 492 6 114 756
24 C 362
28 B 494 8 196 361
59 B 495 7 158 721
19 B 496 8 151 506
18 S 497 7 196 950
43 C 192
18 C 418
21 C 426
22 C 117
9 B 502 6 166 828
40 C 455
13 S 504 0 100 865
10 S 505 8 156 688
57 C 451
29 C 372
58 S 508 3 189 146
31 B 509 9 199 554
7 S 510 8 127 762
25 S 511 9 198 324
31 B 512 7 146 156
51 S 513 1 148 474
63 C 247
0 B 515 8 160 359
29 B 516 8 140 226
17 S 517 8 123 500
13 B 518 2 192 554
18 S 519 7 177 599
7 S 520 0 100 355
51 S 521 6 178 733
13 C 318
56 S 523 0 151 664
62 S 524 2 122 737
22 C 117
55 S 526 0 196 656
57 B 527 2 120 123
31 S 528 8 191 628
57 B 529 1 169 241
41 S 530 1 161 215
37 B 531 6 153 539
36 S 532 5 169 297
25 C 137
16 B 534 7 199 463
15 S 535 0 118 411
8 B 536 2 166 909
26 B 537 3 139 198
38 C 242
54 S 539 1 178 217
63 C 247
44 S 541 8 124 69
49 S 542 8 165 498
52 C 199
44 B 544 4 130 114
6 C 121
47 B 546 8 167 270
20 B 547 9 120 805
17 C 434
16 B 549 4 150 506
34 C 302
53 B 551 6 125 333
24 S 552 6 116 377
38 B 553 6 144 760
45 B 554 4 126 285
35 C 473
50 B 556 5 130 76
61 S 557 0 197 154
49 S 558 7 196 712
35 C 171
21 B 560 3 197 255
8 S 561 2 101 967
53 S 562 6 191 665
62 B 563 0 152 176
52 S 564 2 114 550
5 B 565 5 172 571
23 S 566 5 173 710
3 B 567 8 155 536
44 S 568 9 154 51
13 C 196
7 C 347
58 B 571 0 196 181
37 S 572 9 130 527
18 S 573 4 185 500
20 B 574 3 117 814
5 S 575 7 183 892
45 B 576 9 121 81
50 C 189
47 B 578 1 145 302
35 C 417
1 C 272
47 C 135
11 B 582 6 161 312
17 S 583 8 113 889
18 S 584 0 159 262
61 C 233
12 S 586 4 196 550
17 C 146
29 B 588 5 145 597
51 S 589 3 148 892
34 S 590 9 134 139
12 B 591 3 144 614
32 C 194
22 C 283
3 S 594 1 192 263
58 S 595 1 141 556
19 C 411
5 S 597 5 142 672
36 C 373
37 S 599 3 148 273
29 S 600 7 190 665
62 B 601 1 157 173
34 C 176
25 C 450
14 S 604 5 183 948
38 C 140
27 B 606 2 178 158
22 B 607 8 168 317
55 S 608 6 123 914
61 B 609 8 192 823
43 B 610 2 113 44
2 S 611 1 125 495
48 S 612 0 112 350
6 C 488
6 B 614 4 166 373
18 B 615 9 148 881
47 S 616 7 170 174
59 C 468
38 C 303
37 S 619 5 161 910
1 S 620 2 115 110
61 B 621 1 143 528
12 S 622 2 163 550
41 C 530
45 B 624 4 167 49
43 C 257
48 S 626 6 191 772
16 B 627 2 122 418
58 C 595
51 S 629 2 166 211
26 S 630 3 190 811
54 S 631 1 196 922
6 S 632 1 145 120
23 B 633 1 190 664
58 B 634 0 134 449
23 B 635 1 165 305
3 B 636 3 152 447
7 B 637 1 160 87
29 C 516
28 C 131
6 C 121
63 B 641 4 154 96
6 S 642 1 198 489
41 C 472
63 C 313
21 C 310
20 B 646 2 178 142
27 B 647 2 200 277
22 S 648 1 108 595
