tests/64_threads/sample_84.in
64
o
24 S 101 6 138 787
27 S 102 0 108 981
57 S 103 8 145 312
53 S 104 7 122 898
63 S 105 5 144 677
42 B 106 7 122 816
5 B 107 5 186 707
61 B 108 5 173 857
31 B 109 0 145 827
53 S 110 0 144 757
15 S 111 8 191 176
51 S 112 8 180 195
23 B 113 5 177 584
51 C 112
26 B 116 8 124 791
21 S 118 6 146 106
25 B 119 8 137 927
19 B 121 5 120 144
46 B 123 5 126 828
4 B 124 9 193 52
5 S 125 2 200 541
1 S 127 1 103 760
6 S 128 4 133 875
18 S 129 4 121 562
28 B 131 8 184 279
60 S 134 4 144 921
21 C 118
49 B 137 0 175 816
3 B 138 3 109 561
25 S 139 8 190 165
18 C 129
61 B 143 1 127 449
52 B 144 1 150 972
31 C 109
53 C 110
49 C 137
42 C 106
61 B 151 6 121 170
5 C 125
25 S 153 6 111 827
27 B 154 7 139 550
39 B 155 7 129 686
21 S 157 6 120 512
23 B 158 9 136 94
52 C 144
43 S 160 7 135 354
39 C 155
30 S 162 3 163 112
41 S 163 7 110 394
57 S 164 5 113 117
17 B 165 2 154 854
25 C 119
11 B 168 9 121 916
31 C 109
52 B 170 7 144 174
0 S 172 3 171 999
5 B 173 8 124 960
39 B 174 0 152 427
18 C 129
6 B 177 5 120 834
46 C 123
4 C 124
49 S 180 1 148 129
47 S 181 7 133 781
35 S 182 9 104 546
44 B 183 3 184 160
16 B 184 0 196 222
52 S 185 1 170 52
24 B 187 6 190 466
27 S 188 8 169 602
55 B 189 1 177 393
7 S 190 5 157 59
41 C 163
48 B 192 2 189 416
60 B 193 1 180 725
11 B 194 4 192 612
8 S 195 8 120 183
11 C 168
26 S 197 1 146 1000
27 B 198 1 189 881
44 B 201 4 111 199
52 C 185
36 S 203 1 105 907
46 C 123
0 S 205 9 169 134
15 S 206 3 141 390
32 S 207 2 162 602
19 S 208 5 174 726
45 S 209 5 116 905
7 B 210 1 102 459
19 S 211 3 177 68
6 B 212 5 103 879
59 B 214 2 171 56
41 C 163
52 B 217 3 140 227
20 S 219 4 137 164
7 C 190
34 S 221 1 110 774
19 B 222 9 119 531
42 S 223 2 124 788
12 B 224 1 118 967
32 S 225 9 109 946
23 S 226 6 171 290
58 S 228 2 165 669
8 B 229 6 179 125
55 B 230 7 178 780
49 B 231 4 139 58
52 S 232 2 125 343
40 S 234 0 117 658
21 C 118
18 C 129
60 B 239 1 114 372
26 B 240 3 120 402
15 C 111
58 S 242 4 153 579
22 B 243 5 167 827
26 C 240
23 C 113
6 B 246 9 129 879
21 C 157
3 S 248 3 167 983
59 B 249 1 121 950
30 C 162
52 B 251 4 115 844
18 S 252 8 178 913
8 S 253 5 164 583
2 S 254 5 160 291
35 S 255 3 145 511
14 B 256 1 184 18
53 C 104
59 C 249
23 B 259 3 144 581
8 B 262 5 117 702
9 S 263 2 182 21
33 S 264 2 194 907
33 C 264
48 S 266 5 131 967
6 S 267 3 108 52
6 C 128
24 S 269 5 136 659
16 S 270 5 162 353
25 B 271 4 180 218
25 S 272 7 162 737
61 B 273 4 186 642
55 C 230
51 B 275 2 166 520
4 S 276 9 120 585
3 C 248
24 C 269
40 S 279 5 157 840
41 B 280 5 161 243
45 C 209
27 C 154
32 S 283 1 138 114
5 S 284 7 180 183
49 B 285 2 199 138
39 C 174
9 B 287 8 127 801
33 B 288 0 142 456
4 C 124
5 B 290 8 163 115
59 C 249
45 S 292 2 160 554
0 B 293 2 159 465
49 S 294 1 143 529
17 C 165
14 S 296 4 147 61
35 B 297 5 105 947
4 S 298 5 124 205
17 C 165
57 B 300 7 124 615
22 B 301 3 102 679
30 S 302 7 109 549
41 C 163
44 C 183
27 B 305 4 184 137
52 S 306 5 165 502
39 C 155
8 C 262
60 B 309 0 114 289
46 S 311 6 122 616
18 B 312 7 152 31
6 S 313 8 112 767
60 S 314 3 176 450
27 S 315 0 191 38
43 C 160
26 S 317 5 102 501
26 C 317
11 S 320 2 160 801
28 B 321 3 181 224
22 S 322 7 184 271
61 S 323 2 136 641
12 C 224
36 S 325 4 153 646
47 S 326 2 114 230
39 B 327 6 141 286
25 S 328 8 144 36
33 C 288
4 B 330 5 118 308
2 S 331 7 127 134
56 S 332 2 162 494
18 B 333 7 185 93
27 C 305
21 C 157
39 S 337 4 111 957
12 S 338 8 130 788
23 B 339 3 132 759
33 C 288
9 C 263
61 C 323
55 B 344 8 155 400
11 B 345 8 187 188
37 S 346 7 122 109
15 C 111
59 C 214
42 C 106
21 S 352 8 136 447
26 S 353 3 199 559
60 B 354 2 197 428
39 C 174
17 B 356 4 101 163
55 S 357 4 117 980
39 C 174
59 S 359 3 169 466
2 B 360 0 102 31
36 B 361 8 189 575
12 C 224
9 C 287
40 B 364 6 140 681
26 B 365 5 183 449
43 S 366 0 153 359
14 S 368 3 143 839
17 B 369 3 153 211
9 B 370 5 152 180
45 C 209
41 B 372 3 141 253
51 B 373 2 117 185
2 C 254
34 C 221
7 C 190
57 C 300
1 B 378 8 108 312
36 S 379 4 119 586
24 B 380 1 138 164
34 S 381 8 197 909
39 S 382 6 111 377
12 B 383 4 188 195
39 B 384 0 143 583
59 B 385 1 143 475
22 S 386 7 120 803
50 S 388 5 170 750
41 B 389 8 112 439
51 C 373
14 C 296
6 S 392 7 109 403
34 C 381
62 B 394 5 148 858
30 S 395 0 139 759
37 S 396 9 196 958
37 C 396
42 S 398 0 131 257
22 C 243
25 S 400 4 188 791
45 S 401 8 112 743
33 C 264
25 C 153
42 S 404 5 148 51
14 S 405 5 152 278
20 B 406 9 159 963
55 B 407 4 167 731
57 C 103
42 C 106
14 S 410 8 152 678
3 S 411 8 145 164
11 B 412 5 172 539
43 C 366
43 C 160
54 S 415 6 156 810
30 S 416 5 124 51
51 C 275
41 B 418 0 115 48
52 B 419 6 140 309
20 C 219
60 C 239
23 B 422 0 159 56
45 B 423 2 109 351
31 C 109
60 S 425 9 131 29
55 S 426 1 109 547
30 C 162
47 B 428 2 112 423
38 S 429 9 163 485
33 B 430 6 183 444
48 C 192
18 C 312
20 C 219
36 C 361
6 S 435 2 100 672
32 S 436 5 189 920
8 B 437 7 170 637
1 S 438 0 148 951
21 C 118
43 S 440 5 188 418
31 S 441 0 194 709
51 B 442 9 191 930
40 B 443 3 130 761
56 C 332
42 C 106
38 C 429
20 C 406
11 C 412
30 B 450 5 114 773
51 C 112
46 S 452 1 191 128
31 S 453 1 127 280
13 S 454 2 144 990
23 S 455 7 125 286
30 B 456 3 141 221
27 S 457 8 139 687
21 B 458 1 177 138
24 B 459 7 134 701
19 S 460 9 115 568
49 C 285
59 C 359
12 B 463 4 123 612
38 S 464 6 200 969
33 B 465 7 188 334
43 C 366
13 S 467 2 132 36
50 C 388
14 S 469 2 181 629
14 S 470 7 156 811
38 C 464
40 C 279
56 B 473 6 187 564
36 C 361
36 B 475 2 116 42
2 S 476 8 194 442
51 B 477 6 140 252
8 C 437
55 B 479 8 198 295
44 B 480 5 169 179
38 B 481 4 125 584
39 C 327
4 C 276
37 S 484 0 142 899
13 B 485 4 147 450
37 B 486 2 159 735
1 C 438
55 S 489 2 193 47
5 S 490 3 113 430
24 S 491 3 106 430
51 B 492 0 155 365
62 S 493 5 154 324
34 B 494 2 169 333
61 B 495 5 162 281
59 B 496 5 133 931
15 B 497 6 198 55
26 S 498 3 187 764
13 B 499 2 162 581
25 C 272
7 C 210
63 C 105
30 S 503 9 105 573
59 S 504 9 168 754
2 C 254
43 B 506 9 190 376
26 S 507 0 104 21
40 C 234
24 S 509 2 149 18
54 B 510 3 101 962
61 S 511 6 132 28
41 B 512 3 129 559
54 S 513 9 117 320
6 B 514 5 128 13
43 B 515 6 197 91
28 C 131
20 C 219
55 B 518 5 178 580
25 S 519 0 174 634
46 C 452
46 C 452
11 C 320
60 C 425
3 B 524 7 148 985
45 B 525 5 145 201
50 C 388
52 B 527 2 182 297
33 B 528 7 189 578
51 C 275
6 S 530 6 159 977
38 B 531 4 195 415
53 S 532 3 183 753
10 S 533 4 124 697
39 S 534 7 188 437
15 B 535 6 128 245
52 S 536 7 171 359
14 C 469
5 C 125
11 B 539 8 189 577
53 C 532
43 S 541 4 116 711
7 B 542 1 154 389
57 B 543 8 171 991
32 S 544 2 106 341
56 C 332
3 B 546 9 176 434
38 S 547 2 164 889
32 S 548 0 159 414
52 C 232
13 S 550 0 119 914
25 B 551 1 192 381
57 B 552 3 164 390
2 C 331
38 S 554 8 172 429
61 C 143
51 S 556 0 134 787
48 B 557 2 111 594
37 S 558 0 173 444
23 B 559 0 135 872
39 C 155
23 B 561 8 149 307
31 B 562 4 133 327
31 B 563 3 181 622
2 B 564 5 116 951
38 B 565 6 104 259
10 C 533
9 C 370
9 B 568 5 114 512
26 S 569 9 115 402
21 C 458
43 C 506
40 C 279
28 B 573 4 181 45
12 S 574 5 177 812
52 C 527
26 S 576 2 110 432
18 C 333
55 C 230
15 S 579 7 137 374
4 C 124
51 C 373
17 C 369
37 C 558
53 S 584 3 181 161
42 B 585 4 137 913
29 B 586 0 188 401
20 B 587 8 168 240
8 B 588 8 174 367
33 B 589 0 116 926
56 B 590 0 193 400
35 S 591 6 193 798
58 B 592 8 105 186
3 S 593 3 108 284
40 S 594 4 186 102
30 B 595 0 104 578
48 C 557
34 B 597 2 152 689
15 S 598 4 107 550
63 C 105
2 B 600 3 112 925
54 S 601 9 105 578
49 B 602 1 172 832
47 C 326
26 B 604 3 195 411
20 B 605 7 200 777
59 B 606 1 109 96
44 S 607 5 182 859
56 B 608 7 158 134
39 S 609 9 183 103
9 C 263
4 C 330
39 C 609
14 S 613 1 119 595
45 B 614 7 131 644
36 S 615 8 113 29
39 B 616 0 136 19
22 B 617 0 130 440
49 B 618 7 130 525
12 C 574
17 S 620 6 164 213
50 S 621 6 173 479
26 S 622 9 148 364
29 C 586
53 B 624 7 100 970
3 C 248
59 B 626 9 117 383
26 S 627 2 110 920
61 S 628 5 116 459
38 C 565
14 B 630 2 147 105
14 C 630
5 C 490
45 B 633 5 177 937
61 B 634 6 123 455
27 B 635 4 172 661
62 B 636 6 187 924
47 B 637 3 125 394
15 B 638 2 164 479
43 S 639 9 174 218
12 S 640 0 103 882
26 C 116
15 S 642 9 149 985
34 C 597
14 S 644 5 105 765
51 S 645 7 152 550
53 B 646 4 131 641
